Workbook

Sheet Fixed Income
B1: Ticker/CUSIP | C1: Description | D1: Coupon Rate | E1: Current Price | F1: Share Count | G1: Value | H1: % of Porfolio | I1: Target % of Portfolio | K1: Purchase Price | L1: Purchase Date | M1: Coupon Value | N1: % Return to Date | O1: % Return to Date Over Benchmark ETF | Q1: Latest Thesis | R1: Thesis Date | S1: Thesis Price Target | T1: % Premium Over Thesis
A2: Fixed Income
B3: 629377CC4 | C3: =VLOOKUP($B3, 'Sector Holdings'!$B$2:$C$130, 2, FALSE) -> #N/A | D3: 0.06625 | E3: =OFFSET('Sector Holdings'!$A$1:$H$18, MATCH("Fixed Income", 'Sector Holdings'!$A$1:$A$130, 0), 5, $B$14) -> #REF! | F3: 25 | G3: 22847.5 | H3: 0.0083292957 | I3: 0.015 | K3: 1007.19 | L3: 43864 | M3: =ROUND(DATEDIF(L3,TODAY(),"M")/6,0)*(D3*1000) -> 795 | N3: =(((E3+M3)/K3-1) ) -> #REF! | Q3: =OFFSET('Sector Holdings'!$A$1:$M$18, MATCH("Fixed Income", 'Sector Holdings'!$A$1:$A$130, 0), 17, $B$14) -> #REF! | R3: Hold | S3: 44292 | T3: 1000 | U3: -0.0861
B4: 38148BAD0 | C4: =VLOOKUP(B4, 'Sector Holdings'!$B$2:$C$130, 2, FALSE) -> #N/A | D4: 0.05 | E4: 1058.6 | F4: 25 | G4: 26465 | H4: 0.0096480933 | I4: 0.015 | K4: 1092.5 | L4: 44823 | M4: =ROUND(DATEDIF(L4,TODAY(),"M")/6,0)*(D4*1000) -> 350 | N4: =(((E4+M4)/K4-1) ) -> 0.28933638 | R4: Buy at 1.5% | T4: 1000 | U4: 0.0586
B5: 3133ELEN0 | C5: =VLOOKUP(B5, 'Sector Holdings'!$B$2:$C$130, 2, FALSE) -> FFCB Corp. 2.25 12/18/29 | D5: 0.0225 | E5: 992.2 | F5: 29 | G5: 28773.8 | H5: 0.010489791 | I5: 0.015 | K5: 907.92 | L5: 44830 | M5: =ROUND(DATEDIF(L5,TODAY(),"M")/6,0)*(D5*1000) -> 157.5 | N5: =(((E5+M5)/K5-1) ) -> 0.266301 | R5: Buy at 1.5% | S5: 44824 | T5: 1000 | U5: -0.0078
B6: 449669AK6 | C6: =VLOOKUP(B6, 'Sector Holdings'!$B$2:$C$130, 2, FALSE) -> MOS 7.3 01/15/28 Corp | D6: 0.073 | E6: 909.4 | F6: 33 | G6: 30010.2 | H6: 0.010940533 | I6: 0.015 | K6: 854.34 | L6: 45230 | M6: =ROUND(DATEDIF(L6,TODAY(),"M")/6,0)*(D6*1000) -> 365 | N6: =(((E6+M6)/K6-1) ) -> 0.49167779 | R6: Buy at 1.5% | S6: 45230 | T6: 1000 | U6: -0.0906
B7: 05530QAP5 | C7: =VLOOKUP(B7, 'Sector Holdings'!$B$2:$C$130, 2, FALSE) -> BTI 4.448 03/16/28 Corp | D7: 0.04448 | E7: 996.9 | F7: 43 | G7: 42866.7 | H7: 0.015627505 | I7: 0.02 | K7: 948.61 | L7: 45261 | M7: =ROUND(DATEDIF(L7,TODAY(),"M")/6,0)*(D7*1000) -> 177.92 | N7: =(((E7+M7)/K7-1) ) -> 0.2384647 | R7: Buy at 2% | S7: 45261 | T7: 1000 | U7: -0.0031
B8: BBN | C8: =VLOOKUP(B8, 'Sector Holdings'!$B$2:$C$130, 2, FALSE) -> #N/A | E8: 992.9 | F8: 22 | G8: 21843.8 | H8: 0.0079633864 | I8: 0.0094 | K8: 961.68 | L8: 45359 | M8: =100*4.777% -> 4.777 | N8: =((E8+M8)/K8-1) -> 0.03743137 | R8: Buy at 0.95% | S8: 45356 | T8: 956.4 | U8: 0.038163948
B9: 912797LL9 | C9: =VLOOKUP(B9, 'Sector Holdings'!$B$2:$C$130, 2, FALSE) -> #N/A | D9: 0 | E9: 993.8 | F9: 47 | G9: 46708.6 | H9: 0.01702811 | I9: 0.02 | K9: 1038.1 | L9: 45561 | M9: =ROUND(DATEDIF(L9,TODAY(),"M")/6,0)*(D9*1000) -> 0 | N9: 88.96 | R9: Buy at 2% | S9: 45552 | T9: 1040 | U9: -0.044423077
B10: AGG | C10: =VLOOKUP(B10, 'Sector Holdings'!$B$2:$C$130, 2, FALSE) -> iShares Aggregate Bond ETF | E10: 1105.4 | F10: 43 | G10: 47532.2 | H10: 0.017328362 | I10: 0.02 | K10: 1120.55 | L10: 45590 | N10: =(E10/K10-1) -> -0.013520146 | R10: Buy at 2% | S10: 45590 | T10: 1120 | U10: -0.013035714
B11: Cash | E11: 964.2 | F11: 25 | G11: 24105 | H11: 0.0087877305 | I11: 0.01 | K11: 966.6 | L11: 45611 | R11: Buy at 1% | S11: 45610 | T11: 966 | U11: -0.001863354
A12: Sector Total | E12: 1006.5 | F12: 33 | G12: 33214.5 | H12: 0.012108694 | I12: 0.0125 | K12: 993.26 | L12: 45701 | N12: =(G12/K12-1) -> 32.439885 | R12: Buy at 1.25% | S12: 45700 | T12: 1000 | U12: 0.0065
E13: 1008.94 | F13: 24 | G13: 24214.56 | H13: 0.0088276718 | I13: 0.01 | K13: 1003.1 | L13: 45748 | R13: Buy at 1.00% | S13: 45741 | T13: 1000 | U13: 0.00894
A14: # Of FI Holdings | B14: 13 | E14: 100.44 | F14: 0 | G14: 0 | H14: 0 | I14: 0 | K14: 105.59 | L14: 44113 | R14: NA | S14: NA | T14: NA | U14: NA
G15: 38148.02 | H15: 0.013907261

Sheet Copy of Fixed Income
B1: Ticker/CUSIP | C1: Description | D1: Coupon Rate | E1: Compound Frequency | F1: Current Price | G1: Share Count | H1: Value | I1: % of Porfolio | J1: Target % of Portfolio | L1: Purchase Price | M1: Purchase Date | N1: Coupon Value Earned PTD | O1: % Return to Date | P1: % Return to Date Over Benchmark ETF | R1: Latest Thesis | S1: Thesis Date | T1: Thesis Price Target | U1: % Premium Over Thesis
A2: Fixed Income | W2: Number of FI Holdings | X2: 11
A3: =OFFSET('Sector Holdings'!$A$1:$H$18, MATCH("Fixed Income", 'Sector Holdings'!$A$1:$A$130, 0), 0, $X$2+2,3) -> #REF! | B3: 3133ELEN0 | C3: FFCB Corp. 2.25 12/18/29 | D3: 0.0225 | F3: =OFFSET('Sector Holdings'!$A$1:$H$18, MATCH("Fixed Income", 'Sector Holdings'!$A$1:$A$130, 0), 5, $X$2+2,8) -> #REF! | G3: 25 | H3: 22847.5 | I3: 0.0083292957 | J3: 0.015 | L3: 1007.19 | M3: 43864 | N3: =ROUNDDOWN(DATEDIF(M3,TODAY(),"M")/6,0)*(D3*1000) -> 270 | O3: =OFFSET('Sector Holdings'!$A$1:$H$18, MATCH("Fixed Income", 'Sector Holdings'!$A$1:$A$130, 0), 13, $X$2+2,1) -> #REF! | R3: =OFFSET('Sector Holdings'!$A$1:$H$18, MATCH("Fixed Income", 'Sector Holdings'!$A$1:$A$130, 0), 18, $X$2+2) -> #REF! | S3: 44292 | T3: 1000 | U3: -0.0861
B4: 449669AK6 | C4: MOS 7.3 01/15/28 Corp | D4: 0.073 | F4: 1058.6 | G4: 25 | H4: 26465 | I4: 0.0096480933 | J4: 0.015 | L4: 1092.5 | M4: 44823 | N4: =ROUND(DATEDIF(M4,TODAY(),"M")/6,0)*(D4*1000) -> 511 | O4: -0.031029748 | R4: Buy at 1.5% | T4: 1000 | U4: 0.0586
B5: 05530QAP5 | C5: BTI 4.448 03/16/28 Corp | D5: 0.04448 | F5: 992.2 | G5: 29 | H5: 28773.8 | I5: 0.010489791 | J5: 0.015 | L5: 907.92 | M5: 44830 | N5: =ROUND(DATEDIF(M5,TODAY(),"M")/6,0)*(D5*1000) -> 311.36 | O5: 0.092827562 | R5: Buy at 1.5% | S5: 44824 | T5: 1000 | U5: -0.0078
B6: 3133EJEP0 | C6: FFCB 3.50 03/02/34 | D6: 0.0425 | F6: 909.4 | G6: 33 | H6: 30010.2 | I6: 0.010940533 | J6: 0.015 | L6: 854.34 | M6: 45230 | N6: =ROUND(DATEDIF(M6,TODAY(),"M")/6,0)*(D6*1000) -> 212.5 | O6: 0.06444741 | R6: Buy at 1.5% | S6: 45230 | T6: 1000 | U6: -0.0906
B7: 695114BZ0 | C7: Pacificorp 5.25 06/15/35 | D7: 0.035 | F7: 996.9 | G7: 43 | H7: 42866.7 | I7: 0.015627505 | J7: 0.02 | L7: 948.61 | M7: 45261 | N7: =ROUND(DATEDIF(M7,TODAY(),"M")/6,0)*(D7*1000) -> 140 | O7: 0.050906063 | R7: Buy at 2% | S7: 45261 | T7: 1000 | U7: -0.0031
B8: 517834AH0 | C8: LVS 2.9 06/25/25 | D8: 0.0525 | F8: 992.9 | G8: 22 | H8: 21843.8 | I8: 0.0079633864 | J8: 0.0094 | L8: 961.68 | M8: 45359 | N8: =100*4.777% -> 4.777 | O8: 0.032464021 | R8: Buy at 0.95% | S8: 45356 | T8: 956.4 | U8: 0.038163948
B9: 61747YFT7 | C9: MS 5.32 07/19/35 | D9: 0.029 | F9: 993.8 | G9: 47 | H9: 46708.6 | I9: 0.01702811 | J9: 0.02 | L9: 1038.1 | M9: 45561 | N9: =ROUND(DATEDIF(M9,TODAY(),"M")/6,0)*(D9*1000) -> 87 | O9: -0.042674116 | R9: Buy at 2% | S9: 45552 | T9: 1040 | U9: -0.044423077
B10: 822582AD4 | C10: RDSALN 6.375 12/15/38 | D10: 0.0532 | F10: 1105.4 | G10: 43 | H10: 47532.2 | I10: 0.017328362 | J10: 0.02 | L10: 1120.55 | M10: 45590 | N10: =ROUND(DATEDIF(M10,TODAY(),"M")/6,0)*(D10*1000) -> 159.6 | O10: -0.013520146 | R10: Buy at 2% | S10: 45590 | T10: 1120 | U10: -0.013035714
B11: 626717AP7 | C11: MUR 6 10/01/32 | D11: 0.06375 | F11: 964.2 | G11: 25 | H11: 24105 | I11: 0.0087877305 | J11: 0.01 | L11: 966.6 | M11: 45611 | N11: =ROUND(DATEDIF(M11,TODAY(),"M")/6,0)*(D11*1000) -> 191.25 | O11: -0.0024829299 | R11: Buy at 1% | S11: 45610 | T11: 966 | U11: -0.001863354
B12: 446413BA3 | C12: HII Corp 5.353 1/15/30 | D12: 0.06 | F12: 1006.5 | G12: 33 | H12: 33214.5 | I12: 0.012108694 | J12: 0.0125 | L12: 993.26 | M12: 45701 | N12: =ROUND(DATEDIF(M12,TODAY(),"M")/6,0)*(D12*1000) -> 120 | O12: 0.013329843 | R12: Buy at 1.25% | S12: 45700 | T12: 1000 | U12: 0.0065
B13: 29379VBM4 | C13: EPD Corp SOFR+3.248 08/16/77 | F13: 1008.94 | G13: 24 | H13: 24214.56 | I13: 0.0088276718 | J13: 0.01 | L13: 1003.1 | M13: 45748 | N13: =ROUND(DATEDIF(M13,TODAY(),"M")/6,0)*(D13*1000) -> 0 | O13: 0.0058219519 | R13: Buy at 1.00% | S13: 45741 | T13: 1000 | U13: 0.00894
B14: AGG | C14: iShares Aggregate Bond ETF | F14: 100.44 | G14: 0 | H14: 0 | I14: 0 | J14: 0 | L14: 105.59 | M14: 44113 | O14: -0.048773558 | R14: NA | S14: NA | T14: NA | U14: NA
B15: Cash | H15: 38148.02 | I15: 0.013907261

Sheet Holdings by Weight
A1: Ticker | B1: Description | C1: Sector | D1: Price | E1: Shares | F1: Value | G1: Portfolio Weight | H1: Sector Weight
A2: Total Cash | C2: Total Cash | F2: =VLOOKUP($A$2, 'Sector Holdings'!$A$3:$I$130, 8, FALSE) -> 144078 | G2: =VLOOKUP($A$2, 'Sector Holdings'!$A$3:$I$130, 9, FALSE) -> 0.054049094 | K2: Weight | L2: Value
A3: SPY | B3: =VLOOKUP($A3, 'Sector Holdings'!$B$3:$C$130, 2, FALSE) -> SPDR S&P 500 ETF | C3: Quant | D3: =VLOOKUP($A3, 'Sector Holdings'!$B$3:$H$130, 5, FALSE) -> 682.51 | E3: =VLOOKUP($A3, 'Sector Holdings'!$B$3:$I$130, 6, FALSE) -> 0 | F3: =D3*E3 -> 0 | G3: =VLOOKUP($A3, 'Sector Holdings'!$B$3:$I$130, 8, FALSE) -> 0 | H3: =IF(F3>0, F3/SUMIF(C:C,C3, F:F), "N/A") -> N/A | J3: Equities Total | K3: =L3/$L$6 -> #N/A | L3: =L6-L5-L4 -> #N/A
A4: AGG | B4: =VLOOKUP($A4, 'Sector Holdings'!$B$3:$C$130, 2, FALSE) -> iShares Aggregate Bond ETF | C4: Fixed Income | D4: =VLOOKUP($A4, 'Sector Holdings'!$B$3:$H$130, 5, FALSE) -> 101.07 | E4: =VLOOKUP($A4, 'Sector Holdings'!$B$3:$I$130, 6, FALSE) -> 0 | F4: =D4*E4 -> 0 | G4: =VLOOKUP($A4, 'Sector Holdings'!$B$3:$I$130, 8, FALSE) -> 0 | H4: =IF(F4>0, F4/SUMIF(C:C,C4, F:F), "N/A") -> N/A | J4: Fixed Income | K4: =L4/$L$6 -> #N/A | L4: =SUMIF(C:C, "Fixed Income", F:F) -> #N/A
A5: XLY | B5: =VLOOKUP($A5, 'Sector Holdings'!$B$3:$C$130, 2, FALSE) -> SPDR Discretionary ETF | C5: Consumer Discretionary | D5: =VLOOKUP($A5, 'Sector Holdings'!$B$3:$H$130, 5, FALSE) -> 114.52 | E5: =VLOOKUP($A5, 'Sector Holdings'!$B$3:$I$130, 6, FALSE) -> 0 | F5: =D5*E5 -> 0 | G5: =VLOOKUP($A5, 'Sector Holdings'!$B$3:$I$130, 8, FALSE) -> 0 | H5: =IF(F5>0, F5/SUMIF(C:C,C5, F:F), "N/A") -> N/A | J5: Cash | K5: =L5/$L$6 -> 0.054049094 | L5: =SUMIF(C:C, "Total Cash", F:F) -> 144078
A6: XLP | B6: =VLOOKUP($A6, 'Sector Holdings'!$B$3:$C$130, 2, FALSE) -> SPDR Consumer Staples ETF | C6: Consumer Staples | D6: =VLOOKUP($A6, 'Sector Holdings'!$B$3:$H$130, 5, FALSE) -> 88.74 | E6: =VLOOKUP($A6, 'Sector Holdings'!$B$3:$I$130, 6, FALSE) -> 0 | F6: =D6*E6 -> 0 | G6: =VLOOKUP($A6, 'Sector Holdings'!$B$3:$I$130, 8, FALSE) -> 0 | H6: =IF(F6>0, F6/SUMIF(C:C,C6, F:F), "N/A") -> N/A | J6: Total Portfolio | K6: =SUM(K3:K5) -> #N/A | L6: ='Sector Holdings'!H121 -> 2665687.6
A7: XLE | B7: =VLOOKUP($A7, 'Sector Holdings'!$B$3:$C$130, 2, FALSE) -> SPDR Energy ETF | C7: Energy | D7: =VLOOKUP($A7, 'Sector Holdings'!$B$3:$H$130, 5, FALSE) -> 55.16 | E7: =VLOOKUP($A7, 'Sector Holdings'!$B$3:$I$130, 6, FALSE) -> 0 | F7: =D7*E7 -> 0 | G7: =VLOOKUP($A7, 'Sector Holdings'!$B$3:$I$130, 8, FALSE) -> 0 | H7: =IF(F7>0, F7/SUMIF(C:C,C7, F:F), "N/A") -> N/A
A8: XLF | B8: =VLOOKUP($A8, 'Sector Holdings'!$B$3:$C$130, 2, FALSE) -> SPDR Financials ETF | C8: Financials | D8: =VLOOKUP($A8, 'Sector Holdings'!$B$3:$H$130, 5, FALSE) -> 50.89 | E8: =VLOOKUP($A8, 'Sector Holdings'!$B$3:$I$130, 6, FALSE) -> 0 | F8: =D8*E8 -> 0 | G8: =VLOOKUP($A8, 'Sector Holdings'!$B$3:$I$130, 8, FALSE) -> 0 | H8: =IF(F8>0, F8/SUMIF(C:C,C8, F:F), "N/A") -> N/A
A9: XLV | B9: =VLOOKUP($A9, 'Sector Holdings'!$B$3:$C$130, 2, FALSE) -> SPDR Healthcare ETF | C9: Healthcare | D9: =VLOOKUP($A9, 'Sector Holdings'!$B$3:$H$130, 5, FALSE) -> 158.19 | E9: =VLOOKUP($A9, 'Sector Holdings'!$B$3:$I$130, 6, FALSE) -> 0 | F9: =D9*E9 -> 0 | G9: =VLOOKUP($A9, 'Sector Holdings'!$B$3:$I$130, 8, FALSE) -> 0 | H9: =IF(F9>0, F9/SUMIF(C:C,C9, F:F), "N/A") -> N/A
A10: XLI | B10: =VLOOKUP($A10, 'Sector Holdings'!$B$3:$C$130, 2, FALSE) -> SPDR Industrials ETF | C10: Industrials | D10: =VLOOKUP($A10, 'Sector Holdings'!$B$3:$H$130, 5, FALSE) -> 175.12 | E10: =VLOOKUP($A10, 'Sector Holdings'!$B$3:$I$130, 6, FALSE) -> 0 | F10: =D10*E10 -> 0 | G10: =VLOOKUP($A10, 'Sector Holdings'!$B$3:$I$130, 8, FALSE) -> 0 | H10: =IF(F10>0, F10/SUMIF(C:C,C10, F:F), "N/A") -> N/A
A11: XLRE | B11: =VLOOKUP($A11, 'Sector Holdings'!$B$3:$C$130, 2, FALSE) -> SPDR REITs ETF | C11: REITs | D11: =VLOOKUP($A11, 'Sector Holdings'!$B$3:$H$130, 5, FALSE) -> 43.68 | E11: =VLOOKUP($A11, 'Sector Holdings'!$B$3:$I$130, 6, FALSE) | F11: =D11*E11 -> 0 | G11: =VLOOKUP($A11, 'Sector Holdings'!$B$3:$I$130, 8, FALSE) -> 0 | H11: =IF(F11>0, F11/SUMIF(C:C,C11, F:F), "N/A") -> N/A
A12: XLK | B12: =VLOOKUP($A12, 'Sector Holdings'!$B$3:$C$130, 2, FALSE) -> SPDR Technology ETF | C12: Technology | D12: =VLOOKUP($A12, 'Sector Holdings'!$B$3:$H$130, 5, FALSE) -> 139.25 | E12: =VLOOKUP($A12, 'Sector Holdings'!$B$3:$I$130, 6, FALSE) -> 0 | F12: =D12*E12 -> 0 | G12: =VLOOKUP($A12, 'Sector Holdings'!$B$3:$I$130, 8, FALSE) -> 0 | H12: =IF(F12>0, F12/SUMIF(C:C,C12, F:F), "N/A") -> N/A
A13: XLC | B13: =VLOOKUP($A13, 'Sector Holdings'!$B$3:$C$130, 2, FALSE) -> SPDR Communications Services ETF | C13: Media & Telecom | D13: =VLOOKUP($A13, 'Sector Holdings'!$B$3:$H$130, 5, FALSE) -> 116.06 | E13: =VLOOKUP($A13, 'Sector Holdings'!$B$3:$I$130, 6, FALSE) -> 0 | F13: =D13*E13 -> 0 | G13: =VLOOKUP($A13, 'Sector Holdings'!$B$3:$I$130, 8, FALSE) -> 0 | H13: =IF(F13>0, F13/SUMIF(C:C,C13, F:F), "N/A") -> N/A
A14: XLU | B14: =VLOOKUP($A14, 'Sector Holdings'!$B$3:$C$130, 2, FALSE) -> SPDR Utilities ETF | C14: Utilities | D14: =VLOOKUP($A14, 'Sector Holdings'!$B$3:$H$130, 5, FALSE) -> 46.63 | E14: =VLOOKUP($A14, 'Sector Holdings'!$B$3:$I$130, 6, FALSE) -> 0 | F14: =D14*E14 -> 0 | G14: =VLOOKUP($A14, 'Sector Holdings'!$B$3:$I$130, 8, FALSE) -> 0 | H14: =IF(F14>0, F14/SUMIF(C:C,C14, F:F), "N/A") -> N/A
A15: AMZN | B15: =VLOOKUP(A15, 'Sector Holdings'!$B$3:$C$130, 2, FALSE) -> Amazon.com Inc | C15: Consumer Discretionary | D15: =VLOOKUP($A15, 'Sector Holdings'!$B$3:$H$130, 5, FALSE) -> 204.63 | E15: =VLOOKUP($A15, 'Sector Holdings'!$B$3:$I$130, 6, FALSE) -> 425 | F15: =D15*E15 -> 86967.75 | G15: =VLOOKUP($A15, 'Sector Holdings'!$B$3:$I$130, 8, FALSE) -> 0.032624884 | H15: =IF(F15>0, F15/SUMIF(C:C,C15, F:F), "N/A") -> #N/A
A16: GPC | B16: =VLOOKUP(A16, 'Sector Holdings'!$B$3:$C$130, 2, FALSE) -> #N/A | C16: Consumer Discretionary | D16: =VLOOKUP($A16, 'Sector Holdings'!$B$3:$H$130, 5, FALSE) -> #N/A | E16: =VLOOKUP($A16, 'Sector Holdings'!$B$3:$I$130, 6, FALSE) -> #N/A | F16: =D16*E16 -> #N/A | G16: =VLOOKUP($A16, 'Sector Holdings'!$B$3:$I$130, 8, FALSE) -> #N/A | H16: =IF(F16>0, F16/SUMIF(C:C,C16, F:F), "N/A") -> #N/A
A17: LVMUY | B17: =VLOOKUP(A17, 'Sector Holdings'!$B$3:$C$130, 2, FALSE) -> LVMH Moët Hennessy Louis Vuitton | C17: Consumer Discretionary | D17: =VLOOKUP($A17, 'Sector Holdings'!$B$3:$H$130, 5, FALSE) -> 132.36 | E17: =VLOOKUP($A17, 'Sector Holdings'!$B$3:$I$130, 6, FALSE) -> 258 | F17: =D17*E17 -> 34148.88 | G17: =VLOOKUP($A17, 'Sector Holdings'!$B$3:$I$130, 8, FALSE) -> 0.012810533 | H17: =IF(F17>0, F17/SUMIF(C:C,C17, F:F), "N/A") -> #N/A
A18: ABNB | B18: =VLOOKUP(A18, 'Sector Holdings'!$B$3:$C$130, 2, FALSE) -> Airbnb, Inc. | C18: Consumer Discretionary | D18: =VLOOKUP($A18, 'Sector Holdings'!$B$3:$H$130, 5, FALSE) -> 120.9 | E18: =VLOOKUP($A18, 'Sector Holdings'!$B$3:$I$130, 6, FALSE) -> 334 | F18: =D18*E18 -> 40380.6 | G18: =VLOOKUP($A18, 'Sector Holdings'!$B$3:$I$130, 8, FALSE) -> 0.015148287 | H18: =IF(F18>0, F18/SUMIF(C:C,C18, F:F), "N/A") -> #N/A
A19: IMKTA | B19: =VLOOKUP(A19, 'Sector Holdings'!$B$3:$C$130, 2, FALSE) -> #N/A | C19: Consumer Staples | D19: =VLOOKUP($A19, 'Sector Holdings'!$B$3:$H$130, 5, FALSE) -> #N/A | E19: =VLOOKUP($A19, 'Sector Holdings'!$B$3:$I$130, 6, FALSE) -> #N/A | F19: =D19*E19 -> #N/A | G19: =VLOOKUP($A19, 'Sector Holdings'!$B$3:$I$130, 8, FALSE) -> #N/A | H19: =IF(F19>0, F19/SUMIF(C:C,C19, F:F), "N/A") -> #N/A
A20: PM | B20: =VLOOKUP(A20, 'Sector Holdings'!$B$3:$C$130, 2, FALSE) -> Philip Morris International Inc. | C20: Consumer Staples | D20: =VLOOKUP($A20, 'Sector Holdings'!$B$3:$H$130, 5, FALSE) -> 185.24 | E20: =VLOOKUP($A20, 'Sector Holdings'!$B$3:$I$130, 6, FALSE) -> 243 | F20: =D20*E20 -> 45013.32 | G20: =VLOOKUP($A20, 'Sector Holdings'!$B$3:$I$130, 8, FALSE) -> 0.016886195 | H20: =IF(F20>0, F20/SUMIF(C:C,C20, F:F), "N/A") -> #N/A
A21: LNG | B21: =VLOOKUP(A21, 'Sector Holdings'!$B$3:$C$130, 2, FALSE) -> Cheniere Energy | C21: Energy | D21: =VLOOKUP($A21, 'Sector Holdings'!$B$3:$H$130, 5, FALSE) -> 226.62 | E21: =VLOOKUP($A21, 'Sector Holdings'!$B$3:$I$130, 6, FALSE) -> 323 | F21: =D21*E21 -> 73198.26 | G21: =VLOOKUP($A21, 'Sector Holdings'!$B$3:$I$130, 8, FALSE) -> 0.027459429 | H21: =IF(F21>0, F21/SUMIF(C:C,C21, F:F), "N/A") -> #N/A
A22: FANG | B22: =VLOOKUP(A22, 'Sector Holdings'!$B$3:$C$130, 2, FALSE) -> Diamondback Energy Inc | C22: Energy | D22: =VLOOKUP($A22, 'Sector Holdings'!$B$3:$H$130, 5, FALSE) -> 174.82 | E22: =VLOOKUP($A22, 'Sector Holdings'!$B$3:$I$130, 6, FALSE) -> 168 | F22: =D22*E22 -> 29369.76 | G22: =VLOOKUP($A22, 'Sector Holdings'!$B$3:$I$130, 8, FALSE) -> 0.011017705 | H22: =IF(F22>0, F22/SUMIF(C:C,C22, F:F), "N/A") -> #N/A
A23: TTE | B23: =VLOOKUP(A23, 'Sector Holdings'!$B$3:$C$130, 2, FALSE) -> #N/A | C23: Energy | D23: =VLOOKUP($A23, 'Sector Holdings'!$B$3:$H$130, 5, FALSE) -> #N/A | E23: =VLOOKUP($A23, 'Sector Holdings'!$B$3:$I$130, 6, FALSE) -> #N/A | F23: =D23*E23 -> #N/A | G23: =VLOOKUP($A23, 'Sector Holdings'!$B$3:$I$130, 8, FALSE) -> #N/A | H23: =IF(F23>0, F23/SUMIF(C:C,C23, F:F), "N/A") -> #N/A
A24: ICE | B24: =VLOOKUP(A24, 'Sector Holdings'!$B$3:$C$130, 2, FALSE) -> #N/A | C24: Financials | D24: =VLOOKUP($A24, 'Sector Holdings'!$B$3:$H$130, 5, FALSE) -> #N/A | E24: =VLOOKUP($A24, 'Sector Holdings'!$B$3:$I$130, 6, FALSE) -> #N/A | F24: =D24*E24 -> #N/A | G24: =VLOOKUP($A24, 'Sector Holdings'!$B$3:$I$130, 8, FALSE) -> #N/A | H24: =IF(F24>0, F24/SUMIF(C:C,C24, F:F), "N/A") -> #N/A
A25: MS | B25: =VLOOKUP(A25, 'Sector Holdings'!$B$3:$C$130, 2, FALSE) -> #N/A | C25: Financials | D25: =VLOOKUP($A25, 'Sector Holdings'!$B$3:$H$130, 5, FALSE) -> #N/A | E25: =VLOOKUP($A25, 'Sector Holdings'!$B$3:$I$130, 6, FALSE) -> #N/A | F25: =D25*E25 -> #N/A | G25: =VLOOKUP($A25, 'Sector Holdings'!$B$3:$I$130, 8, FALSE) -> #N/A | H25: =IF(F25>0, F25/SUMIF(C:C,C25, F:F), "N/A") -> #N/A
A26: PFG | B26: =VLOOKUP(A26, 'Sector Holdings'!$B$3:$C$130, 2, FALSE) -> Principal Financial Group Inc | C26: Financials | D26: =VLOOKUP($A26, 'Sector Holdings'!$B$3:$H$130, 5, FALSE) -> 93.27 | E26: =VLOOKUP($A26, 'Sector Holdings'!$B$3:$I$130, 6, FALSE) -> 41 | F26: =D26*E26 -> 3824.07 | G26: =VLOOKUP($A26, 'Sector Holdings'!$B$3:$I$130, 8, FALSE) -> 0.0014345529 | H26: =IF(F26>0, F26/SUMIF(C:C,C26, F:F), "N/A") -> #N/A
... A65: 912797LL9 | B65: =VLOOKUP(A65, 'Sector Holdings'!$B$3:$C$130, 2, FALSE) -> #N/A | C65: Fixed Income | D65: =VLOOKUP($A65, 'Sector Holdings'!$B$3:$H$130, 5, FALSE) -> #N/A | E65: =VLOOKUP($A65, 'Sector Holdings'!$B$3:$I$130, 6, FALSE) -> #N/A | F65: =D65*E65 -> #N/A | G65: =VLOOKUP($A65, 'Sector Holdings'!$B$3:$I$130, 8, FALSE) -> #N/A | H65: =IF(F65>0, F65/SUMIF(C:C,C65, F:F), "N/A") -> #N/A
A66: PXD | B66: =VLOOKUP($A66, OFFSET('Sector Holdings'!$A$1:$M$19, MATCH("Quant", 'Sector Holdings'!$A$1:$A$130, 0), 1), 2, FALSE) -> #N/A | C66: Quant (VC2) | D66: =VLOOKUP($A66, 'Sector Holdings'!$B$3:$H$130, 5, FALSE) -> #N/A | E66: =VLOOKUP($A66, OFFSET('Sector Holdings'!$A$1:$M$19, MATCH("Quant", 'Sector Holdings'!$A$1:$A$130, 0), 1), 6, FALSE) -> #N/A | F66: =D66*E66 -> #N/A | G66: =VLOOKUP($A66, OFFSET('Sector Holdings'!$A$1:$M$19, MATCH("Quant", 'Sector Holdings'!$A$1:$A$130, 0), 1), 8, FALSE) -> #N/A | H66: =IF(F66>0, F66/SUMIF(C:C,C66, F:F), "N/A") -> #N/A
A67: MPC | B67: =VLOOKUP($A67, OFFSET('Sector Holdings'!$A$1:$M$19, MATCH("Quant", 'Sector Holdings'!$A$1:$A$130, 0), 1), 2, FALSE) -> #N/A | C67: Quant (VC2) | D67: =VLOOKUP($A67, 'Sector Holdings'!$B$3:$H$130, 5, FALSE) -> #N/A | E67: =VLOOKUP($A67, OFFSET('Sector Holdings'!$A$1:$M$19, MATCH("Quant", 'Sector Holdings'!$A$1:$A$130, 0), 1), 6, FALSE) -> #N/A | F67: =D67*E67 -> #N/A | G67: =VLOOKUP($A67, OFFSET('Sector Holdings'!$A$1:$M$19, MATCH("Quant", 'Sector Holdings'!$A$1:$A$130, 0), 1), 8, FALSE) -> #N/A | H67: =IF(F67>0, F67/SUMIF(C:C,C67, F:F), "N/A") -> #N/A
A68: VNO | B68: =VLOOKUP($A68, OFFSET('Sector Holdings'!$A$1:$M$19, MATCH("Quant", 'Sector Holdings'!$A$1:$A$130, 0), 1), 2, FALSE) -> #N/A | C68: Quant (VC2) | D68: =VLOOKUP($A68, 'Sector Holdings'!$B$3:$H$130, 5, FALSE) -> #N/A | E68: =VLOOKUP($A68, OFFSET('Sector Holdings'!$A$1:$M$19, MATCH("Quant", 'Sector Holdings'!$A$1:$A$130, 0), 1), 6, FALSE) -> #N/A | F68: =D68*E68 -> #N/A | G68: =VLOOKUP($A68, OFFSET('Sector Holdings'!$A$1:$M$19, MATCH("Quant", 'Sector Holdings'!$A$1:$A$130, 0), 1), 8, FALSE) -> #N/A | H68: =IF(F68>0, F68/SUMIF(C:C,C68, F:F), "N/A") -> #N/A
A69: CF | B69: =VLOOKUP($A69, OFFSET('Sector Holdings'!$A$1:$M$19, MATCH("Quant", 'Sector Holdings'!$A$1:$A$130, 0), 1), 2, FALSE) -> #N/A | C69: Quant (VC2) | D69: =VLOOKUP($A69, 'Sector Holdings'!$B$3:$H$130, 5, FALSE) -> #N/A | E69: =VLOOKUP($A69, OFFSET('Sector Holdings'!$A$1:$M$19, MATCH("Quant", 'Sector Holdings'!$A$1:$A$130, 0), 1), 6, FALSE) -> #N/A | F69: =D69*E69 -> #N/A | G69: =VLOOKUP($A69, OFFSET('Sector Holdings'!$A$1:$M$19, MATCH("Quant", 'Sector Holdings'!$A$1:$A$130, 0), 1), 8, FALSE) -> #N/A | H69: =IF(F69>0, F69/SUMIF(C:C,C69, F:F), "N/A") -> #N/A
A70: NRG | B70: =VLOOKUP($A70, OFFSET('Sector Holdings'!$A$1:$M$19, MATCH("Quant", 'Sector Holdings'!$A$1:$A$130, 0), 1), 2, FALSE) -> #N/A | C70: Quant (VC2) | D70: =VLOOKUP($A70, 'Sector Holdings'!$B$3:$H$130, 5, FALSE) -> #N/A | E70: =VLOOKUP($A70, OFFSET('Sector Holdings'!$A$1:$M$19, MATCH("Quant", 'Sector Holdings'!$A$1:$A$130, 0), 1), 6, FALSE) -> #N/A | F70: =D70*E70 -> #N/A | G70: =VLOOKUP($A70, OFFSET('Sector Holdings'!$A$1:$M$19, MATCH("Quant", 'Sector Holdings'!$A$1:$A$130, 0), 1), 8, FALSE) -> #N/A | H70: =IF(F70>0, F70/SUMIF(C:C,C70, F:F), "N/A") -> #N/A
A71: SRE | B71: =VLOOKUP($A71, OFFSET('Sector Holdings'!$A$1:$M$19, MATCH("Quant", 'Sector Holdings'!$A$1:$A$130, 0), 1), 2, FALSE) -> #N/A | C71: Quant (G-Score) | D71: =VLOOKUP($A71, 'Sector Holdings'!$B$3:$H$130, 5, FALSE) -> #N/A | E71: =VLOOKUP($A71, OFFSET('Sector Holdings'!$A$1:$M$19, MATCH("Quant", 'Sector Holdings'!$A$1:$A$130, 0), 1), 6, FALSE) -> #N/A | F71: =D71*E71 -> #N/A | G71: =VLOOKUP($A71, OFFSET('Sector Holdings'!$A$1:$M$19, MATCH("Quant", 'Sector Holdings'!$A$1:$A$130, 0), 1), 8, FALSE) -> #N/A | H71: =IF(F71>0, F71/SUMIF(C:C,C71, F:F), "N/A") -> #N/A
A72: ADM | B72: =VLOOKUP($A72, OFFSET('Sector Holdings'!$A$1:$M$19, MATCH("Quant", 'Sector Holdings'!$A$1:$A$130, 0), 1), 2, FALSE) -> Archer-Daniels-Midland Co | C72: Quant (G-Score) | D72: =VLOOKUP($A72, 'Sector Holdings'!$B$3:$H$130, 5, FALSE) -> 67.98 | E72: =VLOOKUP($A72, OFFSET('Sector Holdings'!$A$1:$M$19, MATCH("Quant", 'Sector Holdings'!$A$1:$A$130, 0), 1), 6, FALSE) -> 59 | F72: =D72*E72 -> 4010.82 | G72: =VLOOKUP($A72, OFFSET('Sector Holdings'!$A$1:$M$19, MATCH("Quant", 'Sector Holdings'!$A$1:$A$130, 0), 1), 8, FALSE) -> 0.0015046099 | H72: =IF(F72>0, F72/SUMIF(C:C,C72, F:F), "N/A") -> #N/A
A73: HST | B73: =VLOOKUP($A73, OFFSET('Sector Holdings'!$A$1:$M$19, MATCH("Quant", 'Sector Holdings'!$A$1:$A$130, 0), 1), 2, FALSE) -> #N/A | C73: Quant (G-Score) | D73: =VLOOKUP($A73, 'Sector Holdings'!$B$3:$H$130, 5, FALSE) -> #N/A | E73: =VLOOKUP($A73, OFFSET('Sector Holdings'!$A$1:$M$19, MATCH("Quant", 'Sector Holdings'!$A$1:$A$130, 0), 1), 6, FALSE) -> #N/A | F73: =D73*E73 -> #N/A | G73: =VLOOKUP($A73, OFFSET('Sector Holdings'!$A$1:$M$19, MATCH("Quant", 'Sector Holdings'!$A$1:$A$130, 0), 1), 8, FALSE) -> #N/A | H73: =IF(F73>0, F73/SUMIF(C:C,C73, F:F), "N/A") -> #N/A
A74: PFE | B74: =VLOOKUP($A74, OFFSET('Sector Holdings'!$A$1:$M$19, MATCH("Quant", 'Sector Holdings'!$A$1:$A$130, 0), 1), 2, FALSE) -> #N/A | C74: Quant (G-Score) | D74: =VLOOKUP($A74, 'Sector Holdings'!$B$3:$H$130, 5, FALSE) -> #N/A | E74: =VLOOKUP($A74, OFFSET('Sector Holdings'!$A$1:$M$19, MATCH("Quant", 'Sector Holdings'!$A$1:$A$130, 0), 1), 6, FALSE) -> #N/A | F74: =D74*E74 -> #N/A | G74: =VLOOKUP($A74, OFFSET('Sector Holdings'!$A$1:$M$19, MATCH("Quant", 'Sector Holdings'!$A$1:$A$130, 0), 1), 8, FALSE) -> #N/A | H74: =IF(F74>0, F74/SUMIF(C:C,C74, F:F), "N/A") -> #N/A
A75: NI | B75: =VLOOKUP($A75, OFFSET('Sector Holdings'!$A$1:$M$19, MATCH("Quant", 'Sector Holdings'!$A$1:$A$130, 0), 1), 2, FALSE) -> #N/A | C75: Quant (G-Score) | D75: =VLOOKUP($A75, 'Sector Holdings'!$B$3:$H$130, 5, FALSE) -> #N/A | E75: =VLOOKUP($A75, OFFSET('Sector Holdings'!$A$1:$M$19, MATCH("Quant", 'Sector Holdings'!$A$1:$A$130, 0), 1), 6, FALSE) -> #N/A | F75: =D75*E75 -> #N/A | G75: =VLOOKUP($A75, OFFSET('Sector Holdings'!$A$1:$M$19, MATCH("Quant", 'Sector Holdings'!$A$1:$A$130, 0), 1), 8, FALSE) -> #N/A | H75: =IF(F75>0, F75/SUMIF(C:C,C75, F:F), "N/A") -> #N/A
A76: LKQ | B76: =VLOOKUP($A76, OFFSET('Sector Holdings'!$A$1:$M$19, MATCH("Quant", 'Sector Holdings'!$A$1:$A$130, 0), 1), 2, FALSE) -> #N/A | C76: Quant (G-Score) | D76: =VLOOKUP($A76, 'Sector Holdings'!$B$3:$H$130, 5, FALSE) -> #N/A | E76: =VLOOKUP($A76, OFFSET('Sector Holdings'!$A$1:$M$19, MATCH("Quant", 'Sector Holdings'!$A$1:$A$130, 0), 1), 6, FALSE) -> #N/A | F76: =D76*E76 -> #N/A | G76: =VLOOKUP($A76, OFFSET('Sector Holdings'!$A$1:$M$19, MATCH("Quant", 'Sector Holdings'!$A$1:$A$130, 0), 1), 8, FALSE) -> #N/A | H76: =IF(F76>0, F76/SUMIF(C:C,C76, F:F), "N/A") -> #N/A
A77: PM | B77: =VLOOKUP($A77, OFFSET('Sector Holdings'!$A$1:$M$19, MATCH("Quant", 'Sector Holdings'!$A$1:$A$130, 0), 1), 2, FALSE) -> #N/A | C77: Quant (G-Score) | D77: =VLOOKUP($A77, 'Sector Holdings'!$B$3:$H$130, 5, FALSE) -> 185.24 | E77: =VLOOKUP($A77, OFFSET('Sector Holdings'!$A$1:$M$19, MATCH("Quant", 'Sector Holdings'!$A$1:$A$130, 0), 1), 6, FALSE) -> #N/A | F77: =D77*E77 -> #N/A | G77: =VLOOKUP($A77, OFFSET('Sector Holdings'!$A$1:$M$19, MATCH("Quant", 'Sector Holdings'!$A$1:$A$130, 0), 1), 8, FALSE) -> #N/A | H77: =IF(F77>0, F77/SUMIF(C:C,C77, F:F), "N/A") -> #N/A
... A80: MRNA | B80: =VLOOKUP($A80, OFFSET('Sector Holdings'!$A$1:$M$19, MATCH("Quant", 'Sector Holdings'!$A$1:$A$130, 0), 1), 2, FALSE) -> #N/A | C80: Quant (G-Score) | D80: =VLOOKUP($A80, 'Sector Holdings'!$B$3:$H$130, 5, FALSE) -> #N/A | E80: =VLOOKUP($A80, OFFSET('Sector Holdings'!$A$1:$M$19, MATCH("Quant", 'Sector Holdings'!$A$1:$A$130, 0), 1), 6, FALSE) -> #N/A | F80: =D80*E80 -> #N/A | G80: =VLOOKUP($A80, OFFSET('Sector Holdings'!$A$1:$M$19, MATCH("Quant", 'Sector Holdings'!$A$1:$A$130, 0), 1), 8, FALSE) -> #N/A | H80: =IF(F80>0, F80/SUMIF(C:C,C80, F:F), "N/A") -> #N/A

Sheet Sector Holdings
B1: Ticker/CUSIP | C1: Description | E1: Last 1Y Performance | F1: Current Price | G1: Share Count | H1: Value | I1: % of Porfolio | J1: Target % of Portfolio | L1: Purchase Price | M1: Purchase Date | N1: % Return to Date | O1: % Return to Date Over Benchmark ETF | P1: % Return to Date Over S&P | Q1: Beta | S1: Latest Thesis | T1: Thesis Date | U1: Thesis Price Target | V1: % Premium Over Thesis
A2: Consumer Discretionary
B3: AMZN | C3: Amazon.com Inc | E3: =IFERROR(__xludf.DUMMYFUNCTION("SPARKLINE(GOOGLEFINANCE(B3, ""price"", TODAY()-365, TODAY(), ""DAILY""))"),"") | F3: =IFERROR(__xludf.DUMMYFUNCTION("IFERROR(GOOGLEFINANCE(B3), 0)"),204.63) -> 204.63 | G3: 425 | H3: =F3*G3 -> 86967.75 | I3: =H3/$H$121 -> 0.032624884 | J3: 0.015 | L3: 90.851349 | M3: 43293.535 | N3: =(F3/L3-1) -> 1.2523606 | O3: =IFERROR(__xludf.DUMMYFUNCTION("N3 - ((GOOGLEFINANCE(""XLY"")/INDEX(GOOGLEFINANCE(""XLY"",""price"",M3),2,2))-1)"),0.21354985343165156) -> 0.21354985 | P3: =IFERROR(__xludf.DUMMYFUNCTION("N3 - ((GOOGLEFINANCE(""SPY"")/INDEX(GOOGLEFINANCE(""SPY"",""price"",M3),2,2))-1)"),-0.19067193099239255) -> -0.19067193 | Q3: =IFERROR(__xludf.DUMMYFUNCTION("IFERROR(GOOGLEFINANCE(B3, ""beta""), ""N/A"")"),1.37) -> 1.37 | S3: Hold | T3: 45748 | U3: 211.08 | V3: =IFERROR(F3/U3-1, "NA") -> -0.030557135
B4: LVMUY | C4: LVMH Moët Hennessy Louis Vuitton | E4: =IFERROR(__xludf.DUMMYFUNCTION("SPARKLINE(GOOGLEFINANCE(B4, ""price"", TODAY()-365, TODAY(), ""DAILY""))"),"") | F4: =IFERROR(__xludf.DUMMYFUNCTION("IFERROR(GOOGLEFINANCE(B4), 0)"),132.36) -> 132.36 | G4: 258 | H4: =F4*G4 -> 34148.88 | I4: =H4/$H$121 -> 0.012810533 | J4: 0.015 | L4: 131.05 | M4: 44676 | N4: =(F4/L4-1) -> 0.0099961847 | O4: =IFERROR(__xludf.DUMMYFUNCTION("N4 - ((GOOGLEFINANCE(""XLY"")/INDEX(GOOGLEFINANCE(""XLY"",""price"",M4),2,2))-1)"),-0.28328444774872463) -> -0.28328445 | P4: =IFERROR(__xludf.DUMMYFUNCTION("N4 - ((GOOGLEFINANCE(""SPY"")/INDEX(GOOGLEFINANCE(""SPY"",""price"",M4),2,2))-1)"),-0.5827554430709658) -> -0.58275544 | Q4: =IFERROR(__xludf.DUMMYFUNCTION("IFERROR(GOOGLEFINANCE(B4, ""beta""), ""N/A"")"),1.14) -> 1.14 | S4: Hold | T4: 45589 | U4: 172.46 | V4: =IFERROR(F4/U4-1, "NA") -> -0.23251769
B5: ABNB | C5: Airbnb, Inc. | E5: =IFERROR(__xludf.DUMMYFUNCTION("SPARKLINE(GOOGLEFINANCE(B5, ""price"", TODAY()-365, TODAY(), ""DAILY""))"),"") | F5: =IFERROR(__xludf.DUMMYFUNCTION("IFERROR(GOOGLEFINANCE(B5), 0)"),120.9) -> 120.9 | G5: 334 | H5: =F5*G5 -> 40380.6 | I5: =H5/$H$121 -> 0.015148287 | J5: 0.015 | L5: 97.8 | M5: 44883 | N5: =(F5/L5-1) -> 0.23619632 | O5: =IFERROR(__xludf.DUMMYFUNCTION("N5 - ((GOOGLEFINANCE(""XLY"")/INDEX(GOOGLEFINANCE(""XLY"",""price"",M5),2,2))-1)"),-0.38820084410216227) -> -0.38820084 | P5: =IFERROR(__xludf.DUMMYFUNCTION("N5 - ((GOOGLEFINANCE(""SPY"")/INDEX(GOOGLEFINANCE(""SPY"",""price"",M5),2,2))-1)"),-0.4871832229354873) -> -0.48718322 | Q5: =IFERROR(__xludf.DUMMYFUNCTION("IFERROR(GOOGLEFINANCE(B5, ""beta""), ""N/A"")"),1.15) -> 1.15 | S5: Hold | T5: 45951 | U5: 138.11 | V5: =IFERROR(F5/U5-1, "NA") -> -0.12461082
B6: EVVTY | C6: Evolution ADR | E6: =IFERROR(__xludf.DUMMYFUNCTION("SPARKLINE(GOOGLEFINANCE(B6, ""price"", TODAY()-365, TODAY(), ""DAILY""))"),"") | F6: =IFERROR(__xludf.DUMMYFUNCTION("IFERROR(GOOGLEFINANCE(B6), 0)"),57.42) -> 57.42 | G6: 608 | H6: =F6*G6 -> 34911.36 | I6: =H6/$H$121 -> 0.013096568 | J6: 0.015 | L6: 90.75699 | M6: 45219 | N6: =(F6/L6-1) -> -0.36732146 | O6: =IFERROR(__xludf.DUMMYFUNCTION("N6 - ((GOOGLEFINANCE(""XLY"")/INDEX(GOOGLEFINANCE(""XLY"",""price"",M6),2,2))-1)"),-0.8771434772629572) -> -0.87714348 | P6: =IFERROR(__xludf.DUMMYFUNCTION("N6 - ((GOOGLEFINANCE(""SPY"")/INDEX(GOOGLEFINANCE(""SPY"",""price"",M6),2,2))-1)"),-0.9877540439933794) -> -0.98775404 | Q6: =IFERROR(__xludf.DUMMYFUNCTION("IFERROR(GOOGLEFINANCE(B6, ""beta""), ""N/A"")"),1.38) -> 1.38 | S6: Hold | T6: 45741 | U6: 96.86 | V6: =IFERROR(F6/U6-1, "NA") -> -0.40718563
B7: XLY | C7: SPDR Discretionary ETF | E7: =IFERROR(__xludf.DUMMYFUNCTION("SPARKLINE(GOOGLEFINANCE(B7, ""price"", TODAY()-365, TODAY(), ""DAILY""))"),"") | F7: =IFERROR(__xludf.DUMMYFUNCTION("IFERROR(GOOGLEFINANCE(B7), 0)"),114.52) -> 114.52 | G7: 0 | H7: =F7*G7 -> 0 | I7: =H7/$H$121 -> 0 | J7: =I7 -> 0 | L7: 179.75 | M7: 45191 | N7: =(F7/L7-1) -> -0.36289291 | Q7: =IFERROR(__xludf.DUMMYFUNCTION("IFERROR(GOOGLEFINANCE(B7, ""beta""), ""N/A"")"),"N/A") -> N/A | S7: NA | T7: NA | U7: NA | V7: =IFERROR(F7/U7-1, "NA") -> NA
A8: Sector Total | H8: =SUM(H3:H7) -> 196408.59 | I8: =H8/$H$121 -> 0.073680273 | J8: 0.08 | L8: =SUMPRODUCT(L3:L7*G3:G7) -> 160268.17 | M8: =AVERAGE(M3:M7) -> 44652.507 | N8: =H8/L8-1 -> 0.22549965 | Q8: =SUMPRODUCT(I3:I5/SUMIF(Q3:Q5, "<>N/A", I3:I5),Q3:Q5) -> 1.2663575
A10: Consumer Staples
B11: PM | C11: Philip Morris International Inc. | E11: =IFERROR(__xludf.DUMMYFUNCTION("SPARKLINE(GOOGLEFINANCE(B11, ""price"", TODAY()-365, TODAY(), ""DAILY""))"),"") | F11: =IFERROR(__xludf.DUMMYFUNCTION("GOOGLEFINANCE(B11)"),185.24) -> 185.24 | G11: 243 | H11: =F11*G11 -> 45013.32 | I11: =H11/$H$121 -> 0.016886195 | J11: 0.015 | L11: 90.63 | M11: 44862 | N11: =(F11/L11-1) -> 1.0439148 | O11: =IFERROR(__xludf.DUMMYFUNCTION("N11 - ((GOOGLEFINANCE(""XLP"")/INDEX(GOOGLEFINANCE(""XLP"",""price"",M11),2,2))-1)"),0.8311226905714939) -> 0.83112269 | P11: =IFERROR(__xludf.DUMMYFUNCTION("N11 - ((GOOGLEFINANCE(""SPY"")/INDEX(GOOGLEFINANCE(""SPY"",""price"",M11),2,2))-1)"),0.28948059917242963) -> 0.2894806 | Q11: =IFERROR(__xludf.DUMMYFUNCTION("IFERROR(GOOGLEFINANCE(B11, ""beta""), ""N/A"")"),0.39) -> 0.39 | S11: Buy at 1.5% | T11: 44859 | U11: 95.36 | V11: =IFERROR(F11/U11-1, "NA") -> 0.94253356
B12: POST | C12: Post Holdings Inc | E12: =IFERROR(__xludf.DUMMYFUNCTION("SPARKLINE(GOOGLEFINANCE(B12, ""price"", TODAY()-365, TODAY(), ""DAILY""))"),"") | F12: =IFERROR(__xludf.DUMMYFUNCTION("GOOGLEFINANCE(B12)"),106.42) -> 106.42 | G12: 612 | H12: =F12*G12 -> 65129.04 | I12: =H12/$H$121 -> 0.02443236 | J12: 0.015 | L12: 85.08 | M12: 45212 | N12: =(F12/L12-1) -> 0.25082276 | O12: =IFERROR(__xludf.DUMMYFUNCTION("N12 - ((GOOGLEFINANCE(""XLP"")/INDEX(GOOGLEFINANCE(""XLP"",""price"",M12),2,2))-1)"),-0.07762035871838835) -> -0.077620359 | P12: =IFERROR(__xludf.DUMMYFUNCTION("N12 - ((GOOGLEFINANCE(""SPY"")/INDEX(GOOGLEFINANCE(""SPY"",""price"",M12),2,2))-1)"),-0.33089219280224835) -> -0.33089219 | Q12: =IFERROR(__xludf.DUMMYFUNCTION("IFERROR(GOOGLEFINANCE(B12, ""beta""), ""N/A"")"),0.44) -> 0.44 | S12: Hold | T12: 45552 | U12: 127.43 | V12: =IFERROR(F12/U12-1, "NA") -> -0.16487483
B13: SFM | C13: Sprouts Farmers Market Inc | E13: =IFERROR(__xludf.DUMMYFUNCTION("SPARKLINE(GOOGLEFINANCE(B13, ""price"", TODAY()-365, TODAY(), ""DAILY""))"),"") | F13: =IFERROR(__xludf.DUMMYFUNCTION("GOOGLEFINANCE(B13)"),71.22) -> 71.22 | G13: 400 | H13: =F13*G13 -> 28488 | I13: =H13/$H$121 -> 0.010686924 | J13: 0.0125 | L13: 43.19 | M13: 45240 | N13: =(F13/L13-1) -> 0.64899282 | O13: =IFERROR(__xludf.DUMMYFUNCTION("N13 - ((GOOGLEFINANCE(""XLP"")/INDEX(GOOGLEFINANCE(""XLP"",""price"",M13),2,2))-1)"),0.3621598757768647) -> 0.36215988 | P13: =IFERROR(__xludf.DUMMYFUNCTION("N13 - ((GOOGLEFINANCE(""SPY"")/INDEX(GOOGLEFINANCE(""SPY"",""price"",M13),2,2))-1)"),0.09998122485466454) -> 0.099981225 | Q13: =IFERROR(__xludf.DUMMYFUNCTION("IFERROR(GOOGLEFINANCE(B13, ""beta""), ""N/A"")"),0.75) -> 0.75 | S13: Trim to 1.25% | T13: 45575 | U13: 115.69 | V13: =IFERROR(F13/U13-1, "NA") -> -0.38438932
B14: XLP | C14: SPDR Consumer Staples ETF | E14: =IFERROR(__xludf.DUMMYFUNCTION("SPARKLINE(GOOGLEFINANCE(B14, ""price"", TODAY()-365, TODAY(), ""DAILY""))"),"") | F14: =IFERROR(__xludf.DUMMYFUNCTION("GOOGLEFINANCE(B14)"),88.74) -> 88.74 | G14: 0 | H14: =F14*G14 -> 0 | I14: =H14/$H$121 -> 0 | J14: =I14 -> 0 | L14: 72.98 | M14: 44594 | N14: =(F14/L14-1) -> 0.21594958 | Q14: =IFERROR(__xludf.DUMMYFUNCTION("IFERROR(GOOGLEFINANCE(B14, ""beta""), ""N/A"")"),"N/A") -> N/A | S14: NA | T14: NA | U14: NA | V14: =IFERROR(F14/U14-1, "NA") -> NA
A15: Sector Total | H15: =SUM(H11:H14) -> 138630.36 | I15: =H15/$H$121 -> 0.052005479 | J15: 0.05 | L15: =SUMPRODUCT(L11:L14*G11:G14) -> 91368.05 | M15: =AVERAGE(M11:M14) -> 44977 | N15: =H15/L15-1 -> 0.51727393 | Q15: =SUMPRODUCT(I11:I13/SUMIF(Q11:Q13, "<>N/A", I11:I13),Q11:Q13) -> 0.48746878
A17: Energy
B18: LNG | C18: Cheniere Energy | E18: =IFERROR(__xludf.DUMMYFUNCTION("SPARKLINE(GOOGLEFINANCE(B18, ""price"", TODAY()-365, TODAY(), ""DAILY""))"),"") | F18: =IFERROR(__xludf.DUMMYFUNCTION("IFERROR(GOOGLEFINANCE(B18), 0)"),226.62) -> 226.62 | G18: 323 | H18: =F18*G18 -> 73198.26 | I18: =H18/$H$121 -> 0.027459429 | J18: 0.0075 | L18: 65.12 | M18: 43580 | N18: =(F18/L18-1) -> 2.4800369 | O18: =IFERROR(__xludf.DUMMYFUNCTION("N18 - ((GOOGLEFINANCE(""XLE"")/INDEX(GOOGLEFINANCE(""XLE"",""price"",M18),2,2))-1)"),1.8359235912514598) -> 1.8359236 | P18: =IFERROR(__xludf.DUMMYFUNCTION("N18 - ((GOOGLEFINANCE(""SPY"")/INDEX(GOOGLEFINANCE(""SPY"",""price"",M18),2,2))-1)"),1.1430740062095994) -> 1.143074 | Q18: =IFERROR(__xludf.DUMMYFUNCTION("IFERROR(GOOGLEFINANCE(B18, ""beta""), ""N/A"")"),0.27) -> 0.27 | S18: Hold | T18: 45566 | U18: 225.45 | V18: =IFERROR(F18/U18-1, "NA") -> 0.0051896208
B19: FANG | C19: Diamondback Energy Inc | E19: =IFERROR(__xludf.DUMMYFUNCTION("SPARKLINE(GOOGLEFINANCE(B19, ""price"", TODAY()-365, TODAY(), ""DAILY""))"),"") | F19: =IFERROR(__xludf.DUMMYFUNCTION("IFERROR(GOOGLEFINANCE(B19), 0)"),174.82) -> 174.82 | G19: 168 | H19: =F19*G19 -> 29369.76 | I19: =H19/$H$121 -> 0.011017705 | J19: 0.015 | L19: 80.61 | M19: 43873 | N19: =(F19/L19-1) -> 1.1687136 | O19: =IFERROR(__xludf.DUMMYFUNCTION("N19 - ((GOOGLEFINANCE(""XLE"")/INDEX(GOOGLEFINANCE(""XLE"",""price"",M19),2,2))-1)"),0.1643530939954938) -> 0.16435309 | P19: =IFERROR(__xludf.DUMMYFUNCTION("N19 - ((GOOGLEFINANCE(""SPY"")/INDEX(GOOGLEFINANCE(""SPY"",""price"",M19),2,2))-1)"),0.14598224502250723) -> 0.14598225 | Q19: =IFERROR(__xludf.DUMMYFUNCTION("IFERROR(GOOGLEFINANCE(B19, ""beta""), ""N/A"")"),0.61) -> 0.61 | S19: Hold | T19: 45610 | U19: 213.57 | V19: =IFERROR(F19/U19-1, "NA") -> -0.18143934
B20: GEV | C20: GE Vernova | E20: =IFERROR(__xludf.DUMMYFUNCTION("SPARKLINE(GOOGLEFINANCE(B20, ""price"", TODAY()-365, TODAY(), ""DAILY""))"),"") | F20: =IFERROR(__xludf.DUMMYFUNCTION("IFERROR(GOOGLEFINANCE(B20), 0)"),822.8) -> 822.8 | G20: 32 | H20: =F20*G20 -> 26329.6 | I20: =H20/$H$121 -> 0.0098772264 | J20: 0.0016 | L20: 146.63 | M20: 45372 | N20: =(F20/L20-1) -> 4.6114029 | O20: =IFERROR(__xludf.DUMMYFUNCTION("N20 - ((GOOGLEFINANCE(""XLI"")/INDEX(GOOGLEFINANCE(""XLI"",""price"",M20),2,2))-1)"),4.217579227662694) -> 4.2175792 | P20: =IFERROR(__xludf.DUMMYFUNCTION("N20 - ((GOOGLEFINANCE(""SPY"")/INDEX(GOOGLEFINANCE(""SPY"",""price"",M20),2,2))-1)"),4.304413191578247) -> 4.3044132 | Q20: =IFERROR(__xludf.DUMMYFUNCTION("IFERROR(GOOGLEFINANCE(B20, ""beta""), ""N/A"")"),"N/A") -> N/A | S20: Hold | T20: 45700 | U20: 336.63 | V20: =IFERROR(F20/U20-1, "NA") -> 1.4442266
B21: SLB | C21: Schlumberger Ltd | E21: =IFERROR(__xludf.DUMMYFUNCTION("SPARKLINE(GOOGLEFINANCE(B21, ""price"", TODAY()-365, TODAY(), ""DAILY""))"),"") | F21: =IFERROR(__xludf.DUMMYFUNCTION("IFERROR(GOOGLEFINANCE(B21), 0)"),50.73) -> 50.73 | G21: 502 | H21: =F21*G21 -> 25466.46 | I21: =H21/$H$121 -> 0.00955343 | J21: 0.007 | L21: 36.691 | M21: 45964 | N21: =(F21/L21-1) -> 0.38262789 | O21: =IFERROR(__xludf.DUMMYFUNCTION("N21 - ((GOOGLEFINANCE(""XLI"")/INDEX(GOOGLEFINANCE(""XLI"",""price"",M21),2,2))-1)"),0.24843100120697104) -> 0.248431 | P21: =IFERROR(__xludf.DUMMYFUNCTION("N21 - ((GOOGLEFINANCE(""SPY"")/INDEX(GOOGLEFINANCE(""SPY"",""price"",M21),2,2))-1)"),0.3838425146950487) -> 0.38384251 | Q21: =IFERROR(__xludf.DUMMYFUNCTION("IFERROR(GOOGLEFINANCE(B21, ""beta""), ""N/A"")"),0.72) -> 0.72 | S21: Buy at 0.7% | T21: 45958 | U21: 47.51 | V21: =IFERROR(F21/U21-1, "NA") -> 0.067775205
B22: XLE | C22: SPDR Energy ETF | E22: =IFERROR(__xludf.DUMMYFUNCTION("SPARKLINE(GOOGLEFINANCE(B22, ""price"", TODAY()-365, TODAY(), ""DAILY""))"),"") | F22: =IFERROR(__xludf.DUMMYFUNCTION("IFERROR(GOOGLEFINANCE(B22), 0)"),55.16) -> 55.16 | G22: 0 | H22: =F22*G22 -> 0 | I22: =H22/$H$121 -> 0 | J22: =I22 -> 0 | L22: 80.25 | M22: 44624 | N22: =(F22/L22-1) -> -0.31264798 | Q22: =IFERROR(__xludf.DUMMYFUNCTION("IFERROR(GOOGLEFINANCE(B22, ""beta""), ""N/A"")"),"N/A") -> N/A | S22: NA | T22: NA | U22: NA | V22: =IFERROR(F22/U22-1, "NA") -> NA
A23: Sector Total | H23: =SUM(H18:H22) -> 154364.08 | I23: =H23/$H$121 -> 0.057907791 | J23: 0.055 | L23: =SUMPRODUCT(L18:L22*G18:G22) -> 57687.282 | M23: =AVERAGE(M18:M22) -> 44682.6 | N23: =H23/L23-1 -> 1.6758772 | Q23: =SUMPRODUCT(I18:I19/SUMIF(Q18:Q19, "<>N/A", I18:I19), Q18:Q19) -> 0.36735704
A25: Financials
B26: FISV | C26: Fiserv Inc | E26: =IFERROR(__xludf.DUMMYFUNCTION("SPARKLINE(GOOGLEFINANCE(B26, ""price"", TODAY()-365, TODAY(), ""DAILY""))"),"") | F26: =IFERROR(__xludf.DUMMYFUNCTION("IFERROR(GOOGLEFINANCE(""ETR:FIV"", ""price""), 0)*GOOGLEFINANCE(""CURRENCY:EURUSD"")"),59.552955000000004) -> 59.552955 | G26: 401 | H26: =F26*G26 -> 23880.735 | I26: =H26/$H$121 -> 0.0089585647 | J26: 0.01 | L26: 94.914 | M26: 44524 | N26: =(F26/L26-1) -> -0.37255879 | O26: =IFERROR(__xludf.DUMMYFUNCTION("N26 - ((GOOGLEFINANCE(""XLF"")/INDEX(GOOGLEFINANCE(""XLF"",""price"",M26),2,2))-1)"),-0.6416360967957501) -> -0.6416361 | P26: =IFERROR(__xludf.DUMMYFUNCTION("N26 - ((GOOGLEFINANCE(""SPY"")/INDEX(GOOGLEFINANCE(""SPY"",""price"",M26),2,2))-1)"),-0.8264400102398154) -> -0.82644001 | Q26: =IFERROR(__xludf.DUMMYFUNCTION("IFERROR(GOOGLEFINANCE(B26, ""beta""), ""N/A"")"),0.78) -> 0.78 | S26: Raise to 1% | T26: 45960 | U26: 117.26 | V26: =IFERROR(F26/U26-1, "NA") -> -0.49212899
B27: ACGL | C27: Arch Capital Group Ltd | E27: =IFERROR(__xludf.DUMMYFUNCTION("SPARKLINE(GOOGLEFINANCE(B27, ""price"", TODAY()-365, TODAY(), ""DAILY""))"),"") | F27: =IFERROR(__xludf.DUMMYFUNCTION("IFERROR(GOOGLEFINANCE(B27), 0)"),98.38) -> 98.38 | G27: 561 | H27: =F27*G27 -> 55191.18 | I27: =H27/$H$121 -> 0.020704294 | J27: 0.0145 | L27: 55.14 | M27: 44790.204 | N27: =(F27/L27-1) -> 0.78418571 | O27: =IFERROR(__xludf.DUMMYFUNCTION("N27 - ((GOOGLEFINANCE(""XLF"")/INDEX(GOOGLEFINANCE(""XLF"",""price"",M27),2,2))-1)"),0.3558949428958471) -> 0.35589494 | P27: =IFERROR(__xludf.DUMMYFUNCTION("N27 - ((GOOGLEFINANCE(""SPY"")/INDEX(GOOGLEFINANCE(""SPY"",""price"",M27),2,2))-1)"),0.18449040850641873) -> 0.18449041 | Q27: =IFERROR(__xludf.DUMMYFUNCTION("IFERROR(GOOGLEFINANCE(B27, ""beta""), ""N/A"")"),0.42) -> 0.42 | S27: Hold | T27: 45706 | U27: 101.5 | V27: =IFERROR(F27/U27-1, "NA") -> -0.030738916
B28: AGM | C28: Farmer Mac | E28: =IFERROR(__xludf.DUMMYFUNCTION("SPARKLINE(GOOGLEFINANCE(B28, ""price"", TODAY()-365, TODAY(), ""DAILY""))"),"") | F28: =IFERROR(__xludf.DUMMYFUNCTION("IFERROR(GOOGLEFINANCE(B28), 0)"),152.99) -> 152.99 | G28: 162 | H28: =F28*G28 -> 24784.38 | I28: =H28/$H$121 -> 0.009297556 | J28: 0.0145 | L28: 147.16 | M28: 45212 | N28: =(F28/L28-1) -> 0.039616744 | O28: =IFERROR(__xludf.DUMMYFUNCTION("N28 - ((GOOGLEFINANCE(""XLF"")/INDEX(GOOGLEFINANCE(""XLF"",""price"",M28),2,2))-1)"),-0.4927530244617777) -> -0.49275302 | P28: =IFERROR(__xludf.DUMMYFUNCTION("N28 - ((GOOGLEFINANCE(""SPY"")/INDEX(GOOGLEFINANCE(""SPY"",""price"",M28),2,2))-1)"),-0.542098204175967) -> -0.5420982 | Q28: =IFERROR(__xludf.DUMMYFUNCTION("IFERROR(GOOGLEFINANCE(B28, ""beta""), ""N/A"")"),0.99) -> 0.99 | S28: Hold | T28: 45729 | U28: 245 | V28: =IFERROR(F28/U28-1, "NA") -> -0.37555102
B29: SPGI | C29: S&P Global Inc | E29: =IFERROR(__xludf.DUMMYFUNCTION("SPARKLINE(GOOGLEFINANCE(B29, ""price"", TODAY()-365, TODAY(), ""DAILY""))"),"") | F29: =IFERROR(__xludf.DUMMYFUNCTION("IFERROR(GOOGLEFINANCE(B29), 0)"),409.79) -> 409.79 | G29: 150 | H29: =F29*G29 -> 61468.5 | I29: =H29/$H$121 -> 0.023059154 | J29: 0.0167 | L29: 442.15124 | M29: 45372 | N29: =(F29/L29-1) -> -0.073190429 | O29: =IFERROR(__xludf.DUMMYFUNCTION("N29 - ((GOOGLEFINANCE(""XLF"")/INDEX(GOOGLEFINANCE(""XLF"",""price"",M29),2,2))-1)"),-0.28774890172851597) -> -0.2877489 | P29: =IFERROR(__xludf.DUMMYFUNCTION("N29 - ((GOOGLEFINANCE(""SPY"")/INDEX(GOOGLEFINANCE(""SPY"",""price"",M29),2,2))-1)"),-0.3801800883092479) -> -0.38018009 | Q29: =IFERROR(__xludf.DUMMYFUNCTION("IFERROR(GOOGLEFINANCE(B29, ""beta""), ""N/A"")"),1.2) -> 1.2 | S29: Buy at 1.67% | T29: 45365 | U29: 505.86 | V29: =IFERROR(F29/U29-1, "NA") -> -0.18991421
B30: SNEX | C30: Stonex Group Inc | E30: =IFERROR(__xludf.DUMMYFUNCTION("SPARKLINE(GOOGLEFINANCE(B30, ""price"", TODAY()-365, TODAY(), ""DAILY""))"),"") | F30: =IFERROR(__xludf.DUMMYFUNCTION("IFERROR(GOOGLEFINANCE(B30), 0)"),127.48) -> 127.48 | G30: 802 | H30: =F30*G30 -> 102238.96 | I30: =H30/$H$121 -> 0.038353691 | J30: 0.0165 | L30: 62.006892 | M30: 45597 | N30: =(F30/L30-1) -> 1.0559005 | O30: =IFERROR(__xludf.DUMMYFUNCTION("N30 - ((GOOGLEFINANCE(""XLF"")/INDEX(GOOGLEFINANCE(""XLF"",""price"",M30),2,2))-1)"),0.9647769940272952) -> 0.96477699 | P30: =IFERROR(__xludf.DUMMYFUNCTION("N30 - ((GOOGLEFINANCE(""SPY"")/INDEX(GOOGLEFINANCE(""SPY"",""price"",M30),2,2))-1)"),0.8606952536067594) -> 0.86069525 | Q30: =IFERROR(__xludf.DUMMYFUNCTION("IFERROR(GOOGLEFINANCE(B30, ""beta""), ""N/A"")"),0.22) -> 0.22 | S30: Buy at 1.65% | T30: 45597 | U30: 101.14 | V30: =IFERROR(F30/U30-1, "NA") -> 0.26043109
B31: NATL | C31: NCR Atleos Corp | E31: =IFERROR(__xludf.DUMMYFUNCTION("SPARKLINE(GOOGLEFINANCE(B31, ""price"", TODAY()-365, TODAY(), ""DAILY""))"),"") | F31: =IFERROR(__xludf.DUMMYFUNCTION("IFERROR(GOOGLEFINANCE(B31), 0)"),40.29) -> 40.29 | G31: 910 | H31: =F31*G31 -> 36663.9 | I31: =H31/$H$121 -> 0.013754012 | J31: 0.0125 | L31: 36.219 | M31: 45964 | N31: =(F31/L31-1) -> 0.11239957 | O31: =IFERROR(__xludf.DUMMYFUNCTION("N31 - ((GOOGLEFINANCE(""XLF"")/INDEX(GOOGLEFINANCE(""XLF"",""price"",M31),2,2))-1)"),0.13656064311234162) -> 0.13656064 | P31: =IFERROR(__xludf.DUMMYFUNCTION("N31 - ((GOOGLEFINANCE(""SPY"")/INDEX(GOOGLEFINANCE(""SPY"",""price"",M31),2,2))-1)"),0.11361419158320618) -> 0.11361419 | Q31: =IFERROR(__xludf.DUMMYFUNCTION("IFERROR(GOOGLEFINANCE(B31, ""beta""), ""N/A"")"),"N/A") -> N/A | S31: Buy at 1.25% | T31: 45958 | U31: 63.07 | V31: =IFERROR(F31/U31-1, "NA") -> -0.36118598
B32: XLF | C32: SPDR Financials ETF | E32: =IFERROR(__xludf.DUMMYFUNCTION("SPARKLINE(GOOGLEFINANCE(B32, ""price"", TODAY()-365, TODAY(), ""DAILY""))"),"") | F32: =IFERROR(__xludf.DUMMYFUNCTION("IFERROR(GOOGLEFINANCE(B32), 0)"),50.89) -> 50.89 | G32: 0 | H32: =F32*G32 -> 0 | I32: =H32/$H$121 -> 0 | J32: =I32 -> 0 | L32: 38.69 | M32: 45317 | N32: =(F32/L32-1) -> 0.31532696 | Q32: =IFERROR(__xludf.DUMMYFUNCTION("IFERROR(GOOGLEFINANCE(B32, ""beta""), ""N/A"")"),"N/A") -> N/A | S32: NA | T32: NA | U32: NA | V32: NA
A33: Sector Total | H33: =SUM(H26:H32) -> 304227.66 | I33: =H33/$H$121 -> 0.11412727 | J33: 0.115 | L33: =SUMPRODUCT(L26:L32*G26:G32) -> 241845.48 | M33: =AVERAGE(M26:M32) -> 45253.743 | N33: =H33/L33-1 -> 0.2579423 | Q33: =SUMPRODUCT(I26:I29/SUMIF(Q26:Q29, "<>N/A", I26:I29),Q26:Q29) -> 0.84745912
A35: Healthcare
B36: TMO | C36: Thermo Fisher Scientific Inc. | E36: =IFERROR(__xludf.DUMMYFUNCTION("SPARKLINE(GOOGLEFINANCE(B36, ""price"", TODAY()-365, TODAY(), ""DAILY""))"),"") | F36: =IFERROR(__xludf.DUMMYFUNCTION("IFERROR(GOOGLEFINANCE(B36), 0)"),509.54) -> 509.54 | G36: 84 | H36: =F36*G36 -> 42801.36 | I36: =H36/$H$121 -> 0.016056405 | J36: 0.015 | L36: 433 | M36: 43768 | N36: =(F36/L36-1) -> 0.17676674 | O36: =IFERROR(__xludf.DUMMYFUNCTION("N36 - ((GOOGLEFINANCE(""XLV"")/INDEX(GOOGLEFINANCE(""XLV"",""price"",M36),2,2))-1)"),-0.49084868962112127) -> -0.49084869 | P36: =IFERROR(__xludf.DUMMYFUNCTION("N36 - ((GOOGLEFINANCE(""SPY"")/INDEX(GOOGLEFINANCE(""SPY"",""price"",M36),2,2))-1)"),-1.0672984894673672) -> -1.0672985 | Q36: =IFERROR(__xludf.DUMMYFUNCTION("IFERROR(GOOGLEFINANCE(B36, ""beta""), ""N/A"")"),0.93) -> 0.93 | S36: Buy at 2% | T36: 45200 | U36: 306.96 | V36: =IFERROR(F36/U36-1, "NA") -> 0.65995569
B37: UNH | C37: UnitedHealth Group Inc | E37: =IFERROR(__xludf.DUMMYFUNCTION("SPARKLINE(GOOGLEFINANCE(B37, ""price"", TODAY()-365, TODAY(), ""DAILY""))"),"") | F37: =IFERROR(__xludf.DUMMYFUNCTION("IFERROR(GOOGLEFINANCE(B37), 0)"),287.76) -> 287.76 | G37: 224 | H37: =F37*G37 -> 64458.24 | I37: =H37/$H$121 -> 0.024180718 | J37: 0.015 | L37: 336.88797 | M37: 44313 | N37: =(F37/L37-1) -> -0.1458288 | O37: =IFERROR(__xludf.DUMMYFUNCTION("N37 - ((GOOGLEFINANCE(""XLV"")/INDEX(GOOGLEFINANCE(""XLV"",""price"",M37),2,2))-1)"),-0.43664887502079863) -> -0.43664887 | P37: =IFERROR(__xludf.DUMMYFUNCTION("N37 - ((GOOGLEFINANCE(""SPY"")/INDEX(GOOGLEFINANCE(""SPY"",""price"",M37),2,2))-1)"),-0.7805049847582402) -> -0.78050498 | Q37: =IFERROR(__xludf.DUMMYFUNCTION("IFERROR(GOOGLEFINANCE(B37, ""beta""), ""N/A"")"),0.41) -> 0.41 | S37: Raise to 3% | T37: 45930 | U37: 450.21 | V37: =IFERROR(F37/U37-1, "NA") -> -0.36083161
B38: VEEV | C38: Veeva Systems Inc. | E38: =IFERROR(__xludf.DUMMYFUNCTION("SPARKLINE(GOOGLEFINANCE(B38, ""price"", TODAY()-365, TODAY(), ""DAILY""))"),"") | F38: =IFERROR(__xludf.DUMMYFUNCTION("IFERROR(GOOGLEFINANCE(B38), 0)"),174.01) -> 174.01 | G38: 223 | H38: =F38*G38 -> 38804.23 | I38: =H38/$H$121 -> 0.014556931 | J38: 0.015 | L38: 181.05 | M38: 44991 | N38: =(F38/L38-1) -> -0.038884286 | O38: =IFERROR(__xludf.DUMMYFUNCTION("N38 - ((GOOGLEFINANCE(""XLV"")/INDEX(GOOGLEFINANCE(""XLV"",""price"",M38),2,2))-1)"),-0.26411858244526687) -> -0.26411858 | P38: =IFERROR(__xludf.DUMMYFUNCTION("N38 - ((GOOGLEFINANCE(""SPY"")/INDEX(GOOGLEFINANCE(""SPY"",""price"",M38),2,2))-1)"),-0.7263023888111114) -> -0.72630239 | Q38: =IFERROR(__xludf.DUMMYFUNCTION("IFERROR(GOOGLEFINANCE(B38, ""beta""), ""N/A"")"),1.08) -> 1.08 | S38: Buy at 1.5% | T38: 44985 | U38: 203.57 | V38: =IFERROR(F38/U38-1, "NA") -> -0.14520804
B39: RPRX | C39: Royalty Pharma plc | E39: =IFERROR(__xludf.DUMMYFUNCTION("SPARKLINE(GOOGLEFINANCE(B39, ""price"", TODAY()-365, TODAY(), ""DAILY""))"),"") | F39: =IFERROR(__xludf.DUMMYFUNCTION("IFERROR(GOOGLEFINANCE(B39), 0)"),45.23) -> 45.23 | G39: 1696 | H39: =F39*G39 -> 76710.08 | I39: =H39/$H$121 -> 0.028776845 | J39: 0.0136 | L39: 28.594829 | M39: 45401 | N39: =(F39/L39-1) -> 0.58175454 | O39: =IFERROR(__xludf.DUMMYFUNCTION("N39 - ((GOOGLEFINANCE(""XLV"")/INDEX(GOOGLEFINANCE(""XLV"",""price"",M39),2,2))-1)"),0.4432874702903298) -> 0.44328747 | P39: =IFERROR(__xludf.DUMMYFUNCTION("N39 - ((GOOGLEFINANCE(""SPY"")/INDEX(GOOGLEFINANCE(""SPY"",""price"",M39),2,2))-1)"),0.2033919952985992) -> 0.203392 | Q39: =IFERROR(__xludf.DUMMYFUNCTION("IFERROR(GOOGLEFINANCE(B39, ""beta""), ""N/A"")"),0.42) -> 0.42 | S39: Buy at 1.36% | T39: 45400 | U39: 40.76 | V39: =IFERROR(F39/U39-1, "NA") -> 0.10966634
B40: MRK | C40: Merck & Co Inc | E40: =IFERROR(__xludf.DUMMYFUNCTION("SPARKLINE(GOOGLEFINANCE(B40, ""price"", TODAY()-365, TODAY(), ""DAILY""))"),"") | F40: =IFERROR(__xludf.DUMMYFUNCTION("IFERROR(GOOGLEFINANCE(B40), 0)"),123.15) -> 123.15 | G40: 332 | H40: =F40*G40 -> 40885.8 | I40: =H40/$H$121 -> 0.015337806 | J40: 0.01 | L40: 83.581 | M40: 45964 | N40: =(F40/L40-1) -> 0.47342099 | O40: =IFERROR(__xludf.DUMMYFUNCTION("N40 - ((GOOGLEFINANCE(""XLV"")/INDEX(GOOGLEFINANCE(""XLV"",""price"",M40),2,2))-1)"),0.3783015743254661) -> 0.37830157 | P40: =IFERROR(__xludf.DUMMYFUNCTION("N40 - ((GOOGLEFINANCE(""SPY"")/INDEX(GOOGLEFINANCE(""SPY"",""price"",M40),2,2))-1)"),0.4746356151057386) -> 0.47463562 | Q40: =IFERROR(__xludf.DUMMYFUNCTION("IFERROR(GOOGLEFINANCE(B40, ""beta""), ""N/A"")"),0.28) -> 0.28 | S40: Buy at 1.00% | T40: 45958 | U40: 109.66 | V40: =IFERROR(F40/U40-1, "NA") -> 0.1230166
B41: XLV | C41: SPDR Healthcare ETF | E41: =IFERROR(__xludf.DUMMYFUNCTION("SPARKLINE(GOOGLEFINANCE(B41, ""price"", TODAY()-365, TODAY(), ""DAILY""))"),"") | F41: =IFERROR(__xludf.DUMMYFUNCTION("IFERROR(GOOGLEFINANCE(B41), 0)"),158.19) -> 158.19 | G41: 0 | H41: =F41*G41 -> 0 | I41: =H41/$H$121 -> 0 | J41: =I41 -> 0 | L41: 139.31 | M41: 45317 | N41: =(F41/L41-1) -> 0.13552509 | Q41: =IFERROR(__xludf.DUMMYFUNCTION("IFERROR(GOOGLEFINANCE(B41, ""beta""), ""N/A"")"),"N/A") -> N/A | S41: NA | T41: NA | U41: NA | V41: =IFERROR(F41/U41-1, "NA") -> NA
A42: Sector Total | H42: =SUM(H36:H41) -> 263659.71 | I42: =H42/$H$121 -> 0.098908705 | J42: 0.1 | L42: =SUMPRODUCT(L36:L41*G36:G41) -> 228454.78 | M42: =AVERAGE(M36:M41) -> 44959 | N42: =H42/L42-1 -> 0.15410023 | Q42: =SUMPRODUCT(I36:I41/SUMIF(Q36:Q41, "<>N/A", I36:I41),Q36:Q41) -> 0.57577234
A44: Industrials
B45: APD | C45: Air Products & Chemicals, Inc. | E45: =IFERROR(__xludf.DUMMYFUNCTION("SPARKLINE(GOOGLEFINANCE(B45, ""price"", TODAY()-365, TODAY(), ""DAILY""))"),"") | F45: =IFERROR(__xludf.DUMMYFUNCTION("IFERROR(GOOGLEFINANCE(B45), 0)"),281.66) -> 281.66 | G45: 106 | H45: =F45*G45 -> 29855.96 | I45: =H45/$H$121 -> 0.011200097 | J45: 0.015 | L45: 233.63859 | M45: 44627 | N45: =(F45/L45-1) -> 0.20553714 | O45: =IFERROR(__xludf.DUMMYFUNCTION("N45 - ((GOOGLEFINANCE(""XLI"")/INDEX(GOOGLEFINANCE(""XLI"",""price"",M45),2,2))-1)"),-0.5868886508904183) -> -0.58688865 | P45: =IFERROR(__xludf.DUMMYFUNCTION("N45 - ((GOOGLEFINANCE(""SPY"")/INDEX(GOOGLEFINANCE(""SPY"",""price"",M45),2,2))-1)"),-0.42169505372141836) -> -0.42169505 | Q45: =IFERROR(__xludf.DUMMYFUNCTION("IFERROR(GOOGLEFINANCE(B45, ""beta""), ""N/A"")"),0.87) -> 0.87 | S45: Trim to 1.5% | T45: 45729 | U45: 294.455 | V45: =IFERROR(F45/U45-1, "NA") -> -0.043453159
...

Sheet Spring 2026 Trades
A1: Ticker | B1: Description | C1: Sector | D1: Trade Type | E1: Shares | F1: Trade Price | G1: Trade Date | H1: % Gain on Sale | I1: Cash Gain/Loss
A2: MPC | B2: =IFERROR(__xludf.DUMMYFUNCTION("GOOGLEFINANCE(A2,""NAME"")"),"Marathon Petroleum Corp") -> Marathon Petroleum Corp | C2: Quant | D2: Sell to Close | E2: 30 | F2: 194.63 | G2: 46057 | H2: =IF(OR(D2="Sell to Trim", D2="Sell to Close"),F2/VLOOKUP(A2, 'Sector Holdings'!$B$3:$M$121, 11, FALSE) - 1, "N/A") -> #N/A | I2: =IFS(D2="Sell to Close", F2*E2*1, D2="Sell to Trim", F2*E2*1, D2="Buy to Add", F2*E2*-1, D2="Buy to Open", F2*E2*-1) -> 5838.9
A3: CHTR | B3: =IFERROR(__xludf.DUMMYFUNCTION("GOOGLEFINANCE(A3,""NAME"")"),"Charter Communications Inc") -> Charter Communications Inc | C3: Quant | D3: Sell to Close | E3: 12 | F3: 226.68 | G3: 46057 | H3: =IF(OR(D3="Sell to Trim", D3="Sell to Close"),F3/VLOOKUP(A3, 'Sector Holdings'!$B$3:$M$121, 11, FALSE) - 1, "N/A") -> #N/A | I3: =IFS(D3="Sell to Close", F3*E3*1, D3="Sell to Trim", F3*E3*1, D3="Buy to Add", F3*E3*-1, D3="Buy to Open", F3*E3*-1) -> 2720.16
A4: CF | B4: =IFERROR(__xludf.DUMMYFUNCTION("GOOGLEFINANCE(A4,""NAME"")"),"CF Industries Holdings, Inc.") -> CF Industries Holdings, Inc. | C4: Quant | D4: Sell to Close | E4: 59 | F4: 93.65 | G4: 46057 | H4: =IF(OR(D4="Sell to Trim", D4="Sell to Close"),F4/VLOOKUP(A4, 'Sector Holdings'!$B$3:$M$121, 11, FALSE) - 1, "N/A") -> #N/A | I4: =IFS(D4="Sell to Close", F4*E4*1, D4="Sell to Trim", F4*E4*1, D4="Buy to Add", F4*E4*-1, D4="Buy to Open", F4*E4*-1) -> 5525.35
A5: WYNN | B5: =IFERROR(__xludf.DUMMYFUNCTION("GOOGLEFINANCE(A5,""NAME"")"),"Wynn Resorts Ltd") -> Wynn Resorts Ltd | C5: Quant | D5: Sell to Close | E5: 52 | F5: 113.69 | G5: 46057 | H5: =IF(OR(D5="Sell to Trim", D5="Sell to Close"),F5/VLOOKUP(A5, 'Sector Holdings'!$B$3:$M$121, 11, FALSE) - 1, "N/A") -> #N/A | I5: =IFS(D5="Sell to Close", F5*E5*1, D5="Sell to Trim", F5*E5*1, D5="Buy to Add", F5*E5*-1, D5="Buy to Open", F5*E5*-1) -> 5911.88
A6: INCY | B6: =IFERROR(__xludf.DUMMYFUNCTION("GOOGLEFINANCE(A6,""NAME"")"),"Incyte Corp") -> Incyte Corp | C6: Quant | D6: Sell to Close | E6: 70 | F6: 101.72 | G6: 46057 | H6: =IF(OR(D6="Sell to Trim", D6="Sell to Close"),F6/VLOOKUP(A6, 'Sector Holdings'!$B$3:$M$121, 11, FALSE) - 1, "N/A") -> -0.021734949 | I6: =IFS(D6="Sell to Close", F6*E6*1, D6="Sell to Trim", F6*E6*1, D6="Buy to Add", F6*E6*-1, D6="Buy to Open", F6*E6*-1) -> 7120.4
A7: PHM | B7: =IFERROR(__xludf.DUMMYFUNCTION("GOOGLEFINANCE(A7,""NAME"")"),"Pultegroup Inc") -> Pultegroup Inc | C7: Quant | D7: Sell to Close | E7: 42 | F7: 133.08 | G7: 46057 | H7: =IF(OR(D7="Sell to Trim", D7="Sell to Close"),F6/VLOOKUP(A6, 'Sector Holdings'!$B$3:$M$121, 11, FALSE) - 1, "N/A") -> -0.021734949 | I7: =IFS(D7="Sell to Close", F7*E7*1, D7="Sell to Trim", F7*E7*1, D7="Buy to Add", F7*E7*-1, D7="Buy to Open", F7*E7*-1) -> 5589.36
A8: EPAM | B8: =IFERROR(__xludf.DUMMYFUNCTION("GOOGLEFINANCE(A8,""NAME"")"),"EPAM Systems Inc") -> EPAM Systems Inc | C8: Quant | D8: Sell to Close | E8: 23 | F8: 181.44 | G8: 46057 | H8: =IF(OR(D8="Sell to Trim", D8="Sell to Close"),F7/VLOOKUP(A7, 'Sector Holdings'!$B$3:$M$121, 11, FALSE) - 1, "N/A") -> -0.0047861203 | I8: =IFS(D8="Sell to Close", F8*E8*1, D8="Sell to Trim", F8*E8*1, D8="Buy to Add", F8*E8*-1, D8="Buy to Open", F8*E8*-1) -> 4173.12
A9: MNST | B9: =IFERROR(__xludf.DUMMYFUNCTION("GOOGLEFINANCE(A9,""NAME"")"),"Monster Beverage Corp") -> Monster Beverage Corp | C9: Quant | D9: Sell to Close | E9: 70 | F9: 81.12 | G9: 46057 | H9: =IF(OR(D9="Sell to Trim", D9="Sell to Close"),F8/VLOOKUP(A8, 'Sector Holdings'!$B$3:$M$121, 11, FALSE) - 1, "N/A") -> #N/A | I9: =IFS(D9="Sell to Close", F9*E9*1, D9="Sell to Trim", F9*E9*1, D9="Buy to Add", F9*E9*-1, D9="Buy to Open", F9*E9*-1) -> 5678.4
A10: XOM | B10: =IFERROR(__xludf.DUMMYFUNCTION("GOOGLEFINANCE(A10,""NAME"")"),"Exxon Mobil Corp") -> Exxon Mobil Corp | C10: Quant | D10: Sell to Close | E10: 39 | F10: 146.52 | G10: 46057 | H10: =IF(OR(D10="Sell to Trim", D10="Sell to Close"),F9/VLOOKUP(A9, 'Sector Holdings'!$B$3:$M$121, 11, FALSE) - 1, "N/A") -> #N/A | I10: =IFS(D10="Sell to Close", F10*E10*1, D10="Sell to Trim", F10*E10*1, D10="Buy to Add", F10*E10*-1, D10="Buy to Open", F10*E10*-1) -> 5714.28
A11: KHC | B11: =IFERROR(__xludf.DUMMYFUNCTION("GOOGLEFINANCE(A11,""NAME"")"),"Kraft Heinz Co") -> Kraft Heinz Co | C11: Quant | D11: Sell to Close | E11: 156 | F11: 24.5 | G11: 46057 | H11: =IF(OR(D11="Sell to Trim", D11="Sell to Close"),F10/VLOOKUP(A10, 'Sector Holdings'!$B$3:$M$121, 11, FALSE) - 1, "N/A") -> #N/A | I11: =IFS(D11="Sell to Close", F11*E11*1, D11="Sell to Trim", F11*E11*1, D11="Buy to Add", F11*E11*-1, D11="Buy to Open", F11*E11*-1) -> 3822
A12: AMZN | B12: =IFERROR(__xludf.DUMMYFUNCTION("GOOGLEFINANCE(A12,""NAME"")"),"Amazon.com Inc") -> Amazon.com Inc | C12: Consumer Discretionary | D12: Buy to Add | E12: 47 | F12: 237.45 | G12: 46057 | H12: =IF(OR(D12="Sell to Trim", D12="Sell to Close"),F11/VLOOKUP(A11, 'Sector Holdings'!$B$3:$M$121, 11, FALSE) - 1, "N/A") -> N/A | I12: =IFS(D12="Sell to Close", F12*E12*1, D12="Sell to Trim", F12*E12*1, D12="Buy to Add", F12*E12*-1, D12="Buy to Open", F12*E12*-1) -> -11160.15
A13: LVMUY | B13: =IFERROR(__xludf.DUMMYFUNCTION("GOOGLEFINANCE(A13,""NAME"")"),"LVMH Moet Hennessy Louis Vuitton SA Unsponsored ADR") -> LVMH Moet Hennessy Louis Vuitton SA Unsponsored ADR | C13: Consumer Discretionary | D13: Buy to Add | E13: 46 | F13: 126.4 | G13: 46057 | H13: =IF(OR(D13="Sell to Trim", D13="Sell to Close"),F13/VLOOKUP(A13, 'Sector Holdings'!$B$3:$M$121, 11, FALSE) - 1, "N/A") -> N/A | I13: =IFS(D13="Sell to Close", F13*E13*1, D13="Sell to Trim", F13*E13*1, D13="Buy to Add", F13*E13*-1, D13="Buy to Open", F13*E13*-1) -> -5814.4
A14: ABNB | B14: =IFERROR(__xludf.DUMMYFUNCTION("GOOGLEFINANCE(A14,""NAME"")"),"Airbnb Inc") -> Airbnb Inc | C14: Consumer Discretionary | D14: Buy to Add | E14: 46 | F14: 124.2 | G14: 46057 | H14: =IF(OR(D14="Sell to Trim", D14="Sell to Close"),F14/VLOOKUP(A14, 'Sector Holdings'!$B$3:$M$121, 11, FALSE) - 1, "N/A") -> N/A | I14: =IFS(D14="Sell to Close", F14*E14*1, D14="Sell to Trim", F14*E14*1, D14="Buy to Add", F14*E14*-1, D14="Buy to Open", F14*E14*-1) -> -5713.2
A15: POST | B15: =IFERROR(__xludf.DUMMYFUNCTION("GOOGLEFINANCE(A15,""NAME"")"),"Post Holdings Inc") -> Post Holdings Inc | C15: Consumer Staples | D15: Sell to Trim | E15: 93 | F15: 103.9 | G15: 46057 | H15: =IF(OR(D15="Sell to Trim", D15="Sell to Close"),F15/VLOOKUP(A15, 'Sector Holdings'!$B$3:$M$121, 11, FALSE) - 1, "N/A") -> 0.22120357 | I15: =IFS(D15="Sell to Close", F15*E15*1, D15="Sell to Trim", F15*E15*1, D15="Buy to Add", F15*E15*-1, D15="Buy to Open", F15*E15*-1) -> 9662.7
A16: SPGI | B16: =IFERROR(__xludf.DUMMYFUNCTION("GOOGLEFINANCE(A16,""NAME"")"),"S&P Global Inc") -> S&P Global Inc | C16: Financials | D16: Buy to Add | E16: 20 | F16: 453.64 | G16: 46057 | H16: =IF(OR(D16="Sell to Trim", D16="Sell to Close"),F16/VLOOKUP(A16, 'Sector Holdings'!$B$3:$M$121, 11, FALSE) - 1, "N/A") -> N/A | I16: =IFS(D16="Sell to Close", F16*E16*1, D16="Sell to Trim", F16*E16*1, D16="Buy to Add", F16*E16*-1, D16="Buy to Open", F16*E16*-1) -> -9072.8
A17: TMO | B17: =IFERROR(__xludf.DUMMYFUNCTION("GOOGLEFINANCE(A17,""NAME"")"),"Thermo Fisher Scientific Inc") -> Thermo Fisher Scientific Inc | C17: Healthcare | D17: Buy to Add | E17: 3 | F17: 574.4 | G17: 46057 | H17: =IF(OR(D17="Sell to Trim", D17="Sell to Close"),F17/VLOOKUP(A17, 'Sector Holdings'!$B$3:$M$121, 11, FALSE) - 1, "N/A") -> N/A | I17: =IFS(D17="Sell to Close", F17*E17*1, D17="Sell to Trim", F17*E17*1, D17="Buy to Add", F17*E17*-1, D17="Buy to Open", F17*E17*-1) -> -1723.2
